ERROR file_lib.py:671:Failed to connect to database: 'my_db'
Traceback (most recent call last):
  File "/Users/pm286/workspace/amilib/test/test_util.py", line 329, in test_logger
    raise Exception("Failed to connect to database: 'my_db'")
Exception: Failed to connect to database: 'my_db'
ERROR file_lib.py:671:Failed to connect to database: 'my_db'
Traceback (most recent call last):
  File "/Users/pm286/workspace/amilib/test/test_util.py", line 329, in test_logger
    raise Exception("Failed to connect to database: 'my_db'")
Exception: Failed to connect to database: 'my_db'
ERROR file_lib.py:671:Failed to connect to database: 'my_db'
Traceback (most recent call last):
  File "/Users/pm286/workspace/amilib/test/test_util.py", line 329, in test_logger
    raise Exception("Failed to connect to database: 'my_db'")
Exception: Failed to connect to database: 'my_db'
ERROR file_lib.py:671:Failed to connect to database: 'my_db'
Traceback (most recent call last):
  File "/Users/pm286/workspace/amilib/test/test_util.py", line 329, in test_logger
    raise Exception("Failed to connect to database: 'my_db'")
Exception: Failed to connect to database: 'my_db'
ERROR file_lib.py:671:Failed to connect to database: 'my_db'
Traceback (most recent call last):
  File "/Users/pm286/workspace/amilib/test/test_util.py", line 329, in test_logger
    raise Exception("Failed to connect to database: 'my_db'")
Exception: Failed to connect to database: 'my_db'
ERROR file_lib.py:671:Failed to connect to database: 'my_db'
Traceback (most recent call last):
  File "/Users/pm286/workspace/amilib/test/test_util.py", line 329, in test_logger
    raise Exception("Failed to connect to database: 'my_db'")
Exception: Failed to connect to database: 'my_db'
ERROR file_lib.py:671:Failed to connect to database: 'my_db'
Traceback (most recent call last):
  File "/Users/pm286/workspace/amilib/test/test_util.py", line 329, in test_logger
    raise Exception("Failed to connect to database: 'my_db'")
Exception: Failed to connect to database: 'my_db'
ERROR file_lib.py:671:Failed to connect to database: 'my_db'
Traceback (most recent call last):
  File "/Users/pm286/workspace/amilib/test/test_util.py", line 329, in test_logger
    raise Exception("Failed to connect to database: 'my_db'")
Exception: Failed to connect to database: 'my_db'
ERROR file_lib.py:671:Failed to connect to database: 'my_db'
Traceback (most recent call last):
  File "/Users/pm286/workspace/amilib/test/test_util.py", line 329, in test_logger
    raise Exception("Failed to connect to database: 'my_db'")
Exception: Failed to connect to database: 'my_db'
ERROR file_lib.py:671:Failed to connect to database: 'my_db'
Traceback (most recent call last):
  File "/Users/pm286/workspace/amilib/test/test_util.py", line 329, in test_logger
    raise Exception("Failed to connect to database: 'my_db'")
Exception: Failed to connect to database: 'my_db'
ERROR file_lib.py:671:Failed to connect to database: 'my_db'
Traceback (most recent call last):
  File "/Users/pm286/workspace/amilib/test/test_util.py", line 329, in test_logger
    raise Exception("Failed to connect to database: 'my_db'")
Exception: Failed to connect to database: 'my_db'
ERROR file_lib.py:671:Failed to connect to database: 'my_db'
Traceback (most recent call last):
  File "/Users/pm286/workspace/amilib/test/test_util.py", line 329, in test_logger
    raise Exception("Failed to connect to database: 'my_db'")
Exception: Failed to connect to database: 'my_db'
ERROR file_lib.py:671:Failed to connect to database: 'my_db'
Traceback (most recent call last):
  File "/Users/pm286/workspace/amilib/test/test_util.py", line 329, in test_logger
    raise Exception("Failed to connect to database: 'my_db'")
Exception: Failed to connect to database: 'my_db'
ERROR file_lib.py:671:Failed to connect to database: 'my_db'
Traceback (most recent call last):
  File "/Users/pm286/workspace/amilib/test/test_util.py", line 329, in test_logger
    raise Exception("Failed to connect to database: 'my_db'")
Exception: Failed to connect to database: 'my_db'
ERROR file_lib.py:671:Failed to connect to database: 'my_db'
Traceback (most recent call last):
  File "/Users/pm286/workspace/amilib/test/test_util.py", line 329, in test_logger
    raise Exception("Failed to connect to database: 'my_db'")
Exception: Failed to connect to database: 'my_db'
